Workbook

Sheet Aufgaben
A1: KFC Event – Aufgaben & Verantwortliche (Treffen 02.10.2026)
A2: Gelbe Felder ausfüllen: Organisiert von, Verantwortlich, Status (Auswahlliste), Bis wann, Bemerkung. Freie Zeilen je Bereich zum Ergänzen.
A4: Bereich | B4: Aufgabe / Material | C4: Menge | D4: Details | E4: Organisiert von | F4: Verantwortlich | G4: Status | H4: Bis wann | I4: Bemerkung
A5: Orga | B5: Haftungsausschluss Boxen | G5: Offen
A6: Orga | B6: Anlage | G6: Offen
A7: Orga | B7: Keine Videos (Hinweis/Regel kommunizieren) | G7: Offen
A8: Orga
A9: Orga
A10: Deko drinnen | B10: Funken-Fahne Schwabe | C10: 1 | G10: Offen
A11: Deko drinnen | B11: LG-Fahnen | G11: Offen
A12: Deko drinnen | B12: Spots (alles was UC hat) | G12: Offen
A13: Deko drinnen | B13: Nebelmaschine | C13: 1 | G13: Offen
A14: Deko drinnen | B14: Beamer mit Livestand | C14: 1 | D14: Live-Stand von der Website | G14: Offen
A15: Deko drinnen
A16: Deko drinnen
A17: Boxring | B17: Paletten | C17: 30 | D17: 3×4×2 = 24 (120×3=360 ≈ 4×80=320) + 4 Schwabi → 30 mit Puffer | G17: Offen
A18: Boxring | B18: OSB-Platten | C18: 8 | G18: Offen
A19: Boxring | B19: Bodenbelag Ring | C19: 11,52 m² | D19: Sportmatten, Gummimatten oder Teppich? | G19: Offen
A20: Boxring | B20: Dachlatten | G20: Offen
A21: Boxring | B21: Stricke oder Spanngurte | G21: Offen
A22: Boxring
A23: Boxring
A24: Bar | B24: Getränkekarte | G24: Offen
A25: Bar | B25: Biergarnituren | C25: 2 | G25: Offen
A26: Bar | B26: Barleute | C26: 6 | G26: Offen
A27: Bar | B27: UCfK-Barverkleidung | G27: Offen
A28: Bar | B28: MX-Zelt | C28: 1 | G28: Offen
A29: Bar | B29: Bier + Kühler | F29: Jonathan | G29: Offen
A30: Bar | B30: Andere Getränke | F30: Hansen | G30: Offen
A31: Bar
A32: Bar
A33: Grillen Schulhof | B33: Speisekarte | G33: Offen
A34: Grillen Schulhof | B34: Grill | C34: 1 | G34: Offen
A35: Grillen Schulhof | B35: Grillmeister | C35: 3 | G35: Offen
A36: Grillen Schulhof | B36: Stehtische | G36: Offen
A37: Grillen Schulhof | B37: Biergarnituren | C37: 2 | G37: Offen
A38: Grillen Schulhof
A39: Grillen Schulhof
A40: Außenbereich / Eingang | B40: MX-Zelt Eingang | C40: 1 | G40: Offen
A41: Außenbereich / Eingang | B41: Roter Teppich | C41: 1 | D41: aus dem Lager | G41: Offen
...

Sheet Übersicht
A1: Übersicht nach Bereich
A3: Bereich | B3: Aufgaben | C3: Offen | D3: In Arbeit | E3: Erledigt | F3: Ohne Verantwortlichen | G3: Fortschritt
A4: Orga | B4: =COUNTIFS(Aufgaben!$A$5:$A$54,A4,Aufgaben!$B$5:$B$54,"<>") | C4: =COUNTIFS(Aufgaben!$A$5:$A$54,A4,Aufgaben!$G$5:$G$54,"Offen") | D4: =COUNTIFS(Aufgaben!$A$5:$A$54,A4,Aufgaben!$G$5:$G$54,"In Arbeit") | E4: =COUNTIFS(Aufgaben!$A$5:$A$54,A4,Aufgaben!$G$5:$G$54,"Erledigt") | F4: =COUNTIFS(Aufgaben!$A$5:$A$54,A4,Aufgaben!$B$5:$B$54,"<>",Aufgaben!$F$5:$F$54,"") | G4: =IFERROR(E4/(B4-COUNTIFS(Aufgaben!$A$5:$A$54,A4,Aufgaben!$G$5:$G$54,"Entfällt")),0)
A5: Deko drinnen | B5: =COUNTIFS(Aufgaben!$A$5:$A$54,A5,Aufgaben!$B$5:$B$54,"<>") | C5: =COUNTIFS(Aufgaben!$A$5:$A$54,A5,Aufgaben!$G$5:$G$54,"Offen") | D5: =COUNTIFS(Aufgaben!$A$5:$A$54,A5,Aufgaben!$G$5:$G$54,"In Arbeit") | E5: =COUNTIFS(Aufgaben!$A$5:$A$54,A5,Aufgaben!$G$5:$G$54,"Erledigt") | F5: =COUNTIFS(Aufgaben!$A$5:$A$54,A5,Aufgaben!$B$5:$B$54,"<>",Aufgaben!$F$5:$F$54,"") | G5: =IFERROR(E5/(B5-COUNTIFS(Aufgaben!$A$5:$A$54,A5,Aufgaben!$G$5:$G$54,"Entfällt")),0)
A6: Boxring | B6: =COUNTIFS(Aufgaben!$A$5:$A$54,A6,Aufgaben!$B$5:$B$54,"<>") | C6: =COUNTIFS(Aufgaben!$A$5:$A$54,A6,Aufgaben!$G$5:$G$54,"Offen") | D6: =COUNTIFS(Aufgaben!$A$5:$A$54,A6,Aufgaben!$G$5:$G$54,"In Arbeit") | E6: =COUNTIFS(Aufgaben!$A$5:$A$54,A6,Aufgaben!$G$5:$G$54,"Erledigt") | F6: =COUNTIFS(Aufgaben!$A$5:$A$54,A6,Aufgaben!$B$5:$B$54,"<>",Aufgaben!$F$5:$F$54,"") | G6: =IFERROR(E6/(B6-COUNTIFS(Aufgaben!$A$5:$A$54,A6,Aufgaben!$G$5:$G$54,"Entfällt")),0)
A7: Bar | B7: =COUNTIFS(Aufgaben!$A$5:$A$54,A7,Aufgaben!$B$5:$B$54,"<>") | C7: =COUNTIFS(Aufgaben!$A$5:$A$54,A7,Aufgaben!$G$5:$G$54,"Offen") | D7: =COUNTIFS(Aufgaben!$A$5:$A$54,A7,Aufgaben!$G$5:$G$54,"In Arbeit") | E7: =COUNTIFS(Aufgaben!$A$5:$A$54,A7,Aufgaben!$G$5:$G$54,"Erledigt") | F7: =COUNTIFS(Aufgaben!$A$5:$A$54,A7,Aufgaben!$B$5:$B$54,"<>",Aufgaben!$F$5:$F$54,"") | G7: =IFERROR(E7/(B7-COUNTIFS(Aufgaben!$A$5:$A$54,A7,Aufgaben!$G$5:$G$54,"Entfällt")),0)
A8: Grillen Schulhof | B8: =COUNTIFS(Aufgaben!$A$5:$A$54,A8,Aufgaben!$B$5:$B$54,"<>") | C8: =COUNTIFS(Aufgaben!$A$5:$A$54,A8,Aufgaben!$G$5:$G$54,"Offen") | D8: =COUNTIFS(Aufgaben!$A$5:$A$54,A8,Aufgaben!$G$5:$G$54,"In Arbeit") | E8: =COUNTIFS(Aufgaben!$A$5:$A$54,A8,Aufgaben!$G$5:$G$54,"Erledigt") | F8: =COUNTIFS(Aufgaben!$A$5:$A$54,A8,Aufgaben!$B$5:$B$54,"<>",Aufgaben!$F$5:$F$54,"") | G8: =IFERROR(E8/(B8-COUNTIFS(Aufgaben!$A$5:$A$54,A8,Aufgaben!$G$5:$G$54,"Entfällt")),0)
A9: Außenbereich / Eingang | B9: =COUNTIFS(Aufgaben!$A$5:$A$54,A9,Aufgaben!$B$5:$B$54,"<>") | C9: =COUNTIFS(Aufgaben!$A$5:$A$54,A9,Aufgaben!$G$5:$G$54,"Offen") | D9: =COUNTIFS(Aufgaben!$A$5:$A$54,A9,Aufgaben!$G$5:$G$54,"In Arbeit") | E9: =COUNTIFS(Aufgaben!$A$5:$A$54,A9,Aufgaben!$G$5:$G$54,"Erledigt") | F9: =COUNTIFS(Aufgaben!$A$5:$A$54,A9,Aufgaben!$B$5:$B$54,"<>",Aufgaben!$F$5:$F$54,"") | G9: =IFERROR(E9/(B9-COUNTIFS(Aufgaben!$A$5:$A$54,A9,Aufgaben!$G$5:$G$54,"Entfällt")),0)
A10: Material | B10: =COUNTIFS(Aufgaben!$A$5:$A$54,A10,Aufgaben!$B$5:$B$54,"<>") | C10: =COUNTIFS(Aufgaben!$A$5:$A$54,A10,Aufgaben!$G$5:$G$54,"Offen") | D10: =COUNTIFS(Aufgaben!$A$5:$A$54,A10,Aufgaben!$G$5:$G$54,"In Arbeit") | E10: =COUNTIFS(Aufgaben!$A$5:$A$54,A10,Aufgaben!$G$5:$G$54,"Erledigt") | F10: =COUNTIFS(Aufgaben!$A$5:$A$54,A10,Aufgaben!$B$5:$B$54,"<>",Aufgaben!$F$5:$F$54,"") | G10: =IFERROR(E10/(B10-COUNTIFS(Aufgaben!$A$5:$A$54,A10,Aufgaben!$G$5:$G$54,"Entfällt")),0)
A11: Technik | B11: =COUNTIFS(Aufgaben!$A$5:$A$54,A11,Aufgaben!$B$5:$B$54,"<>") | C11: =COUNTIFS(Aufgaben!$A$5:$A$54,A11,Aufgaben!$G$5:$G$54,"Offen") | D11: =COUNTIFS(Aufgaben!$A$5:$A$54,A11,Aufgaben!$G$5:$G$54,"In Arbeit") | E11: =COUNTIFS(Aufgaben!$A$5:$A$54,A11,Aufgaben!$G$5:$G$54,"Erledigt") | F11: =COUNTIFS(Aufgaben!$A$5:$A$54,A11,Aufgaben!$B$5:$B$54,"<>",Aufgaben!$F$5:$F$54,"") | G11: =IFERROR(E11/(B11-COUNTIFS(Aufgaben!$A$5:$A$54,A11,Aufgaben!$G$5:$G$54,"Entfällt")),0)
A12: Gesamt | B12: =SUM(B4:B11) | C12: =SUM(C4:C11) | D12: =SUM(D4:D11) | E12: =SUM(E4:E11) | F12: =SUM(F4:F11) | G12: =IFERROR(E12/(B12-COUNTIF(Aufgaben!$G$5:$G$54,"Entfällt")),0)
A14: Wird automatisch aus dem Blatt „Aufgaben“ berechnet.
